---
title: JS错误处理机制
date: 2022-10-23 08:55:10
categories:
  - javascript
tags:
  - javascript
---

## JS错误处理机制

- Error 实例对象
- 原生错误类型
- 自定义错误
- throw 语句
- try...catch
- finally

## Error实例对象

js解析或运行时，一旦发生错误，引擎就会抛出一个错误对象。js原生提供Error构造函数，所有抛出的错误都是这个构造函数的实例

```js
var err = new Error('error');
err.message
```

Error构造函数接收一个参数，表示错误提示。Js语言标准中，`Error` 实例对象必须有 message 属性。大部分的错误实例都有一下属性

- **message**：错误提示信息
- **name**：错误名称（非标准属性）
- **stack**：错误的堆栈（非标准属性）

## 原生错误类型

`Error`实例对象是最一般的错误类型，在它的基础上，JavaScript 还定义了其他6种错误对象。也就是说，存在`Error`的6个派生对象。

### SyntaxError 对象 

`SyntaxError` 对象是解析代码时发生的语法错误

```js
var 1a;
// Uncaught SyntaxError: Invalid or unexpected token
console.log('hello'
// Uncaught SyntaxError: Unexpected string            
```

上面代码的无错误，都是在语法解析阶段就可以发现的



### ReferenceError对象

`ReferenceError`对象是引用一个不存在的变量时发生的错误。

```js
unknowVar;
// Uncaught ReferenceError: unknownVariable is not defined
console.log() = 1;
// Uncaught ReferenceError: Invalid left-hand side in assignment
```

### RangeError对象

`RangeError` 对象是一个值超出有效范围时发生的错误。主要有几种情况，一是数组长度为负数，二是`Number`对象的方法参数超出范围，以及函数堆栈超过最大值。

```js
// 数组长度不得为负数
new Array(-1)
// Uncaught RangeError: Invalid array length
```

### TypeError对象

`TypeError`对象是变量或参数不是预期类型时发生的错误。比如，对字符串、布尔值、数值等原始类型的值使用`new`命令，就会抛出这种错误，因为`new`命令的参数应该是一个构造函数。

```js
new 123
// Uncaught TypeError: 123 is not a constructor
var obj = {};
obj.unkonwnMethod()
// Uncaught TypeError: obj.unknownMethod is not a function
```

上面代码的第二种情况，调用对象不存在的方法，也会抛出`TypeError`错误，因为`obj.unknownMethod`的值是`undefined`，而不是一个函数。

### URIError对象

`URIError` 对象是 URI 相关函数的参数不正确时的错误。

主要涉及`encodeURI()`、`decodeURI()`、`encodeURIComponent()`、`decodeURIComponent()`、`escape()`和`unescape()`这六个函数。

```js
decodeURI('%2')
// URIError: URI malformed
```

### EvalError

`eval`函数没有被正确执行时，会抛出`EvalError`错误。该错误类型已经不再使用了，只是为了保证与以前代码兼容，才继续保留。

### 总结

以上这6种派生错误，连同原始的`Error`对象，都是构造函数。开发者可以使用它们，手动生成错误对象的实例。这些构造函数都接受一个参数，代表错误提示信息（message）。

## 自定义错误

除了 JavaScript 原生提供的七种错误对象，还可以定义自己的错误对象。

```js
function myError(msg){
  this.message = msg || 'error'
  this.name = 'myError'
}
myError.prototype = new Error()
myError.prototype.constructor = myError
new myError()
```

## throw语句

`throw` 语句的作用时手动中断程序执行，抛出一个错误

```js
var x = -1;

if (x <= 0) {
  throw new Error('x 必须为正数');
}
// Uncaught Error: x 必须为正数
```

## try...catch结构

js原生提供了 `try...catch` 语法，允许对错误进行处理

```js
try {
  throw new Error('出错了!');
} catch (e) {
  console.log(e.name + ": " + e.message);
  console.log(e.stack);
}
```

如果你不确定某些代码是否会报错，就可以把它们放在`try...catch`代码块之中，便于进一步对错误进行处理。

## finally语句

`try...catch`结构允许在最后添加一个`finally`代码块，表示不管是否出现错误，都必需在最后运行的语句。

```js
function f() {
  try {
    console.log(0);
    throw 'bug';
  } catch(e) {
    console.log(1);
    return true; // 这句原本会延迟到 finally 代码块结束再执行
    console.log(2); // 不会运行
  } finally {
    console.log(3);
    return false; // 这句会覆盖掉前面那句 return
    console.log(4); // 不会运行
  }

  console.log(5); // 不会运行
}

var result = f();
// 0
// 1
// 3

result
// false
```

以上是代码的执行顺序，以下例子帮助理解

```js
function f() {
  try {
    throw '出错了！';
  } catch(e) {
    console.log('捕捉到内部错误');
    throw e; // 这句原本会等到finally结束再执行
  } finally {
    return false; // 直接返回
  }
}

try {
  f();
} catch(e) {
  // 此处不会执行
  console.log('caught outer "bogus"');
}

//  捕捉到内部错误
```

参考链接

[错误处理机制 - JavaScript 教程 - 网道 (wangdoc.com)](https://wangdoc.com/javascript/features/error)























